<?xml version='1.0'?>

<robot name="my_robot" xmlns:xacro="http://www.ros.org/wiki/xacro">
<xacro:include filename="$(find my_robot)/urdf/my_robot.gazebo" />
  <link name="robot_footprint"></link>

  <joint name="robot_footprint_joint" type="fixed">
    <origin xyz="0 0 0" rpy="0 0 0" />
    <parent link="robot_footprint"/>
    <child link="chassis" />
  </joint>

  <joint type="continuous" name="left_wheel_1_hinge">
    <origin xyz="0.15 0.15 0" rpy="0 0 0"/>
    <child link="left_wheel_1"/>
    <parent link="chassis"/>
    <axis xyz="0 1 0" rpy="0 0 0"/>
    <limit effort="10000" velocity="1000"/>
    <dynamics damping="1.0" friction="1.0"/>
  </joint>

  <joint type="continuous" name="left_wheel_2_hinge">
    <origin xyz="-0.15 0.15 0" rpy="0 0 0"/>
    <child link="left_wheel_2"/>
    <parent link="chassis"/>
    <axis xyz="0 1 0" rpy="0 0 0"/>
    <limit effort="10000" velocity="1000"/>
    <dynamics damping="1.0" friction="1.0"/>
  </joint>
  
   <joint type="continuous" name="right_wheel_1_hinge">
    <origin xyz="0.15 -0.15 0" rpy="0 0 0"/>
    <child link="right_wheel_1"/>
    <parent link="chassis"/>
    <axis xyz="0 1 0" rpy="0 0 0"/>
    <limit effort="10000" velocity="1000"/>
    <dynamics damping="1.0" friction="1.0"/>
  </joint>

   <joint type="continuous" name="right_wheel_2_hinge">
    <origin xyz="-0.15 -0.15 0" rpy="0 0 0"/>
    <child link="right_wheel_2"/>
    <parent link="chassis"/>
    <axis xyz="0 1 0" rpy="0 0 0"/>
    <limit effort="10000" velocity="1000"/>
    <dynamics damping="1.0" friction="1.0"/>
  </joint>
  
  <joint name="camera_joint" type="fixed">
    <origin xyz="0.3 0 0" rpy="0 0 0" />
    <parent link="chassis"/>
    <child link="camera" />
    <axix xyz="0 1 0" />
  </joint>


  <joint name="hokuyo_joint" type="fixed">
    <origin xyz="0.15 0 0.1" rpy="0 0 0" />
    <parent link="chassis"/>
    <child link="hokuyo" />
    <axix xyz="0 1 0" />
  </joint>
   
   
  <link name='chassis'>
    <pose>0 0 0.1 0 0 0</pose>

    <inertial>
      <mass value="15.0"/>
      <origin xyz="0.0 0 0" rpy=" 0 0 0"/>
      <inertia
          ixx="0.1" ixy="0" ixz="0"
          iyy="0.1" iyz="0"
          izz="0.1"
      />
    </inertial>

    <collision name='chassis_collision'>
      <origin xyz="0 0 0" rpy=" 0 0 0"/> 
      <geometry>
        <box size=".6 .25 .12"/>
      </geometry>
    </collision>

    <visual name='chassis_visual'>
      <origin xyz="0 0 0" rpy=" 0 0 0"/>
      <geometry>
        <box size=".6 .25 .12"/>
      </geometry>
    </visual>

  </link>
  
  <link name='left_wheel_1'>
    <pose>0 0 0.05 0 0 0</pose>

    <inertial>
      <mass value="5.0"/>
      <origin xyz="0.0 0 0" rpy=" 0 0 0"/>
      <inertia
          ixx="0.1" ixy="0" ixz="0"
          iyy="0.1" iyz="0"
          izz="0.1"
      />
    </inertial>

    <collision name='left_wheel_1_collision'>
      <origin xyz="0 0 0" rpy=" 0 1.5707 1.5707"/> 
      <geometry>
        <cylinder radius="0.125" length = "0.05"/>
      </geometry>
    </collision>

    <visual name='left_wheel_1_visual'>
      <origin xyz="0 0 0" rpy=" 0 1.5707 1.5707"/>
      <geometry>
        <cylinder radius ="0.125" length = "0.05"/>
      </geometry>
    </visual>
    
  </link>
  
    <link name='left_wheel_2'>
    <pose>0 0 0.05 0 0 0</pose>

    <inertial>
      <mass value="5.0"/>
      <origin xyz="0.0 0 0" rpy=" 0 0 0"/>
      <inertia
          ixx="0.1" ixy="0" ixz="0"
          iyy="0.1" iyz="0"
          izz="0.1"
      />
    </inertial>

    <collision name='left_wheel_2_collision'>
      <origin xyz="0 0 0" rpy=" 0 1.5707 1.5707"/> 
      <geometry>
        <cylinder radius="0.125" length = "0.05"/>
      </geometry>
    </collision>

    <visual name='left_wheel_2_visual'>
      <origin xyz="0 0 0" rpy=" 0 1.5707 1.5707"/>
      <geometry>
        <cylinder radius ="0.125" length = "0.05"/>
      </geometry>
    </visual>
    
  </link>
  
  <link name='right_wheel_1'>
    <pose>0 0 0.05 0 0 0</pose>

    <inertial>
      <mass value="5.0"/>
      <origin xyz="0 0 0" rpy=" 0 0 0"/>
      <inertia
          ixx="0.1" ixy="0" ixz="0"
          iyy="0.1" iyz="0"
          izz="0.1"
      />
    </inertial>

    <collision name='right_wheel_1_collision'>
      <origin xyz="0 0 0" rpy=" 0 1.5707 1.5707"/> 
      <geometry>
        <cylinder radius="0.125" length = "0.05"/>
      </geometry>
    </collision>

    <visual name='right_wheel_1_visual'>
      <origin xyz="0 0 0" rpy=" 0 1.5707 1.5707"/>
      <geometry>
        <cylinder radius ="0.125" length = "0.05"/>
      </geometry>
    </visual>
    
  </link>
  
    <link name='right_wheel_2'>
    <pose>0 0 0.05 0 0 0</pose>

    <inertial>
      <mass value="5.0"/>
      <origin xyz="0 0 0" rpy=" 0 0 0"/>
      <inertia
          ixx="0.1" ixy="0" ixz="0"
          iyy="0.1" iyz="0"
          izz="0.1"
      />
    </inertial>

    <collision name='right_wheel_2_collision'>
      <origin xyz="0 0 0" rpy=" 0 1.5707 1.5707"/> 
      <geometry>
        <cylinder radius="0.125" length = "0.05"/>
      </geometry>
    </collision>

    <visual name='right_wheel_2_visual'>
      <origin xyz="0 0 0" rpy=" 0 1.5707 1.5707"/>
      <geometry>
        <cylinder radius ="0.125" length = "0.05"/>
      </geometry>
    </visual>
    
  </link>

  <link name='camera'>
    <pose>0 0 0.1 0 0 0</pose>

    <inertial>
      <mass value="0.1"/>
      <origin xyz="0 0 0" rpy=" 0 0 0"/>
      <inertia
          ixx="1e-6" ixy="0" ixz="0"
          iyy="1e-6" iyz="0"
          izz="1e-6"
      />
    </inertial>

    <collision name='camera_collision'>
      <origin xyz="0 0 0" rpy=" 0 0 0"/> 
      <geometry>
        <box size="0.05 0.05 0.05" />
      </geometry>
    </collision>

    <visual name='camera_visual'>
      <origin xyz="0 0 0" rpy=" 0 0 0"/>
      <geometry>
        <box size="0.05 0.05 0.05" />
      </geometry>
    </visual>
    
  </link>
  
  <link name='hokuyo'>
    <pose>0 0 0.1 0 0 0</pose>

    <inertial>
      <mass value="1e-5"/>
      <origin xyz="0 0 0" rpy=" 0 0 0"/>
      <inertia
          ixx="1e-6" ixy="0" ixz="0"
          iyy="1e-6" iyz="0"
          izz="1e-6"
      />
    </inertial>

    <collision name='hokuyo_collision'>
      <origin xyz="0 0 0" rpy=" 0 0 0"/> 
      <geometry>
        <box size="0.1 0.1 0.1" />
      </geometry>
    </collision>

    <visual name='hokuyo_visual'>
      <origin xyz="0 0 0" rpy=" 0 0 0"/>
      <geometry>       
      <mesh filename ="package://my_robot/meshes/hokuyo.dae" />
      </geometry>
    </visual>
    
  </link>
  
 <gazebo reference="right_wheel_1" >
    <material>Gazebo/Green</material>
 </gazebo>

 <gazebo reference="left_wheel_1" >
    <material>Gazebo/Green</material>
 </gazebo>

 <gazebo reference="right_wheel_2" >
    <material>Gazebo/Blue</material>
 </gazebo>

 <gazebo reference="left_wheel_2" >
    <material>Gazebo/Blue</material>
 </gazebo>

 <gazebo reference="camera" >
    <material>Gazebo/Red</material>
 </gazebo>

 
</robot>









